<?xml version="1.0"?>
<robot xmlns:xacro="http://www.ros.org/wiki/xacro" name="factory_robot">

  <!-- ============================================================
       工厂移动机器人主 URDF / Xacro 文件
       结构：差速底盘 + _caster_支撑轮 + 激光雷达 + 深度相机
       扩展预留：机械臂安装位（top_mount_link）
       ============================================================ -->

  <!-- 属性参数：便于后续调整尺寸 -->
  <xacro:property name="base_length" value="0.6"/>
  <xacro:property name="base_width"  value="0.4"/>
  <xacro:property name="base_height" value="0.15"/>
  <xacro:property name="base_mass"   value="20.0"/>
  <xacro:property name="wheel_radius" value="0.08"/>
  <xacro:property name="wheel_width"  value="0.04"/>
  <xacro:property name="wheel_mass"   value="1.5"/>
  <xacro:property name="wheel_y_offset" value="0.18"/>
  <xacro:property name="wheel_z_offset" value="-0.03"/>

  <!-- 材质宏 -->
  <xacro:macro name="box_inertia" params="m w h d">
    <inertial>
      <origin xyz="0 0 0" rpy="0 0 0"/>
      <mass value="${m}"/>
      <inertia ixx="${m*(h*h + d*d)/12}" ixy="0" ixz="0"
               iyy="${m*(w*w + d*d)/12}" iyz="0"
               izz="${m*(w*w + h*h)/12}"/>
    </inertial>
  </xacro:macro>

  <xacro:macro name="cylinder_inertia" params="m r h">
    <inertial>
      <origin xyz="0 0 0" rpy="0 0 0"/>
      <mass value="${m}"/>
      <inertia ixx="${m*(3*r*r + h*h)/12}" ixy="0" ixz="0"
               iyy="${m*(3*r*r + h*h)/12}" iyz="0"
               izz="${m*r*r/2}"/>
    </inertial>
  </xacro:macro>

  <!-- ================== BASE LINK ================== -->
  <link name="base_link">
    <visual>
      <origin xyz="0 0 0" rpy="0 0 0"/>
      <geometry>
        <box size="${base_length} ${base_width} ${base_height}"/>
      </geometry>
      <material name="blue">
        <color rgba="0.2 0.4 0.8 1.0"/>
      </material>
    </visual>
    <collision>
      <origin xyz="0 0 0" rpy="0 0 0"/>
      <geometry>
        <box size="${base_length} ${base_width} ${base_height}"/>
      </geometry>
    </collision>
    <xacro:box_inertia m="${base_mass}" w="${base_width}" h="${base_height}" d="${base_length}"/>
  </link>

  <!-- ================== LEFT WHEEL ================== -->
  <link name="left_wheel_link">
    <visual>
      <origin xyz="0 0 0" rpy="${-pi/2} 0 0"/>
      <geometry>
        <cylinder radius="${wheel_radius}" length="${wheel_width}"/>
      </geometry>
      <material name="black">
        <color rgba="0.1 0.1 0.1 1.0"/>
      </material>
    </visual>
    <collision>
      <origin xyz="0 0 0" rpy="${-pi/2} 0 0"/>
      <geometry>
        <cylinder radius="${wheel_radius}" length="${wheel_width}"/>
      </geometry>
    </collision>
    <xacro:cylinder_inertia m="${wheel_mass}" r="${wheel_radius}" h="${wheel_width}"/>
  </link>

  <joint name="left_wheel_joint" type="continuous">
    <parent link="base_link"/>
    <child link="left_wheel_link"/>
    <origin xyz="0 ${wheel_y_offset} ${wheel_z_offset}" rpy="0 0 0"/>
    <axis xyz="0 1 0"/>
  </joint>

  <!-- ================== RIGHT WHEEL ================== -->
  <link name="right_wheel_link">
    <visual>
      <origin xyz="0 0 0" rpy="${-pi/2} 0 0"/>
      <geometry>
        <cylinder radius="${wheel_radius}" length="${wheel_width}"/>
      </geometry>
      <material name="black"/>
    </visual>
    <collision>
      <origin xyz="0 0 0" rpy="${-pi/2} 0 0"/>
      <geometry>
        <cylinder radius="${wheel_radius}" length="${wheel_width}"/>
      </geometry>
    </collision>
    <xacro:cylinder_inertia m="${wheel_mass}" r="${wheel_radius}" h="${wheel_width}"/>
  </link>

  <joint name="right_wheel_joint" type="continuous">
    <parent link="base_link"/>
    <child link="right_wheel_link"/>
    <origin xyz="0 ${-wheel_y_offset} ${wheel_z_offset}" rpy="0 0 0"/>
    <axis xyz="0 1 0"/>
  </joint>

  <!-- ================== CASTER WHEEL (被动支撑) ================== -->
  <link name="caster_wheel_link">
    <visual>
      <origin xyz="0 0 0" rpy="0 0 0"/>
      <geometry>
        <sphere radius="0.04"/>
      </geometry>
      <material name="grey">
        <color rgba="0.5 0.5 0.5 1.0"/>
      </material>
    </visual>
    <collision>
      <origin xyz="0 0 0" rpy="0 0 0"/>
      <geometry>
        <sphere radius="0.04"/>
      </geometry>
    </collision>
    <inertial>
      <mass value="0.5"/>
      <inertia ixx="0.001" ixy="0" ixz="0" iyy="0.001" iyz="0" izz="0.001"/>
    </inertial>
  </link>

  <joint name="caster_wheel_joint" type="fixed">
    <parent link="base_link"/>
    <child link="caster_wheel_link"/>
    <origin xyz="-0.2 0 ${wheel_z_offset + 0.04}" rpy="0 0 0"/>
  </joint>

  <!-- ================== TOP MOUNT (机械臂 / 扩展件预留安装位) ================== -->
  <link name="top_mount_link">
    <visual>
      <origin xyz="0 0 0" rpy="0 0 0"/>
      <geometry>
        <box size="0.2 0.2 0.02"/>
      </geometry>
      <material name="grey"/>
    </visual>
    <collision>
      <origin xyz="0 0 0" rpy="0 0 0"/>
      <geometry>
        <box size="0.2 0.2 0.02"/>
      </geometry>
    </collision>
    <inertial>
      <mass value="0.5"/>
      <inertia ixx="0.001" ixy="0" ixz="0" iyy="0.001" iyz="0" izz="0.001"/>
    </inertial>
  </link>

  <joint name="top_mount_joint" type="fixed">
    <parent link="base_link"/>
    <child link="top_mount_link"/>
    <origin xyz="0 0 ${base_height/2 + 0.01}" rpy="0 0 0"/>
  </joint>

  <!-- ================== 传感器引入 ================== -->
  <xacro:include filename="$(find factory_robot_description)/urdf/sensors/lidar.xacro"/>
  <xacro:include filename="$(find factory_robot_description)/urdf/sensors/depth_camera.xacro"/>

  <!-- 调用传感器宏，安装到 base_link 前上端 -->
  <xacro:lidar_sensor parent="base_link" xyz="0.15 0 ${base_height/2 + 0.08}" rpy="0 0 0"/>
  <xacro:depth_camera_sensor parent="base_link" xyz="0.2 0 ${base_height/2 + 0.05}" rpy="0 0 0"/>

  <!-- Gazebo Ignition 插件（差速控制） -->
  <xacro:include filename="$(find factory_robot_description)/urdf/gazebo_plugins.xacro"/>


  <!-- ================== GRIPPER (1-DOF parallel jaw) ================== -->
  <xacro:include filename="$(find robot_gripper)/urdf/gripper.urdf.xacro"/>
  <xacro:parallel_gripper parent="top_mount_link" xyz="0 0 0.03" rpy="0 0 0"/>
</robot>
